Workbook

Sheet Overview
A1: DRAFT - Marine Cloud Brightening: Cost, Benefit, and Planetary-Scale Assessment
A3: Intent
A4: The intent of this workbook is to do bottom up assessment of marine cloud brightening. The intent is to use the best available academic sources and connect those pieces together for this end to end assessment. Then we work through different delivery mechanisms, whether a dedicated vessel, piggybacking on a cargo ship, fixed platforms, or stationary vessels.
A5: Methodology
A6: Wherever possible, our intent is to use academic sources for inputs. On the last tab, references, you can find all the papers that we pulled data from. In this sense, we're pulling parts of a shelf and attempting to assemble them. As the foundation we take the exact numbers from Daniel Harrison's prototype in the Great Barrier Reef. However, these "parts" weren't built to be put together. This has two effects. One is that we may be connecting them together in the wrong order. The second is there are gaps, which means we make assumptions, which are not academically sourced.
A7: How the Workbook is Organized
A8: The workbook is broken roughly into two parts. The first section is modeling a machine/ship that spits out aerosol particles. The second section is then figuring out what the climate effect and outcome of those particles is.
A9: Particle cost model (tabs 1-4): what it costs to produce and spray particles
A10: 1. Technology Description: the spray machine. CCN product = 30-1000 nm particles (Harrison 2025 convention).
A11: 2. Cost Inputs: the blue input cells (capital, energy, crew, unit costs).
A12: 3a. Outputs - Dedicated Vessel: levelized cost per tonne of aerosol (the anchor number).
A13: 3b/3c/3d: cheaper siting and delivery vs a dedicated vessel (piggyback, fixed platform, stationary).
... A31: Tito Jankowski, tito.jankowski@renphil.org

Sheet 1. Technology Description
A1: DRAFT - Technology Description
A3: System Definition
A4: A single effervescent nozzle: seawater + compressed air + power in, CCN aerosol out. TEA stops at particle production; climatology on subsequent tabs
A6: Particle Production
A7: Quantity | B7: Value | C7: Unit | D7: Notes / Source | E7: Sources
A8: Particle output | B8: 1730000000000 | C8: particles/s | D8: Harrison et al. 2025, Environ. Sci.: Atmos. 5, 1071-1080 (doi:10.1039/d5ea00073d, OA; RSC blocks automated download, get PDF via DOI): ~1.73e12 droplets/s per nozzle. Cross-checks from files held: CS-06 Final Report 2025, p.24: the 2020 sea trial made "an estimated 2.7 x 10^14 droplets per second" from a "100 nozzle fan driven array [that] matched that of a single nozzle characterised under laboratory conditions" (about 2.7e12 per nozzle); CS-06 p.1: current prototype "~10^15 s-1 sea salt aerosols using 320 kilowatts (kW) of energy" (about 1.6e12 per nozzle over 640 nozzles). | E8: Harrison et al. 2025, Environ. Sci.: Atmos. 5, 1071-1080 (doi:10.1039/d5ea00073d).
A9: CCN-production window fraction (30-1000 nm) | B9: 0.71 | D9: Harrison 2025 (doi:10.1039/d5ea00073d): CCN production rate = counts in the 30-1000 nm window (~71%). No separate activation cut (would double-count). Field target window is tighter, CS-06 Final Report 2025, p.12, Fig. 5 caption: "Green shading indicates a MCB target range of 30-800 nm dry diameter." | E9: Harrison et al. 2025, Environ. Sci.: Atmos. 5, 1071-1080 (doi:10.1039/d5ea00073d).
A10: Dry particle diameter | B10: 150 | C10: nm | D10: One important note this model currently does not respond to changes in particle size. It calls all particles equivalent as long as they're within a certain range. Design value stays mass-weighted; mass sits in the large tail. Count mode is much smaller: CS-06 Final Report 2025, p.24: "mode dry aerosol diameter around 40 nm"; ERL 2025 (doi:10.1088/1748-9326/adccd7), p.6: sea-salt plume has "a notable peak at 47.03 nm average". Count-equivalent from the measured count + mass: ~143 nm. | E10: CS-06 Final Report 2025, p.24 + ERL 2025 p.6 (doi:10.1088/1748-9326/adccd7).
A11: Particles per tonne of salt | B11: =1000/B12 -> 2.6198345e+20 | C11: particles/tonne | D11: Field count runs ~15% higher than the lab math (2020 GBR trial; Hernandez-Jaramillo 2025), so cooling cost may come out slightly high. Tab 5a pulls this cell.
A12: Mass per dry particle | B12: =PI()/6*(B10*10^-9)^3*2160 -> 3.8170351e-18 | C12: kg | D12: Sphere volume x dry NaCl density 2160 kg/m3.
A13: CCN-production output (30-1000 nm window) | B13: =B8*B9*B12*86400*1000 -> 405.08331 | C13: g/day | D13: per nozzle particle rate x window fraction x dry mass x time. Window output is the product (Harrison 2025); plume survival charged per-scenario on 5a/6a.
A14: CCN-production output (30-1000 nm window) | B14: =B13/1000000 -> 0.00040508331 | C14: tonne/day
A16: Energy | G16: Nozzle power scenario (selector)
A17: Power | B17: =CHOOSE($H$17,$H$18,$H$19) -> 512 | C17: W | D17: Set by the scenario selector in H17 (1 = measured 512 W, 2 = CS-06 10x energy target 51.2 W). Harrison 2025 (doi:10.1039/d5ea00073d): nozzle power, ~98% air compression. Scale check from file held, CS-06 Final Report 2025, p.1: "The current prototype produces ~10^15 s-1 sea salt aerosols using 320 kilowatts (kW) of energy", about 0.32 W per 1e9 particles/s, i.e. ~550 W per nozzle at 1.73e12/s. Consistent with 512 W. | E17: Harrison et al. 2025, Environ. Sci.: Atmos. 5, 1071-1080 (doi:10.1039/d5ea00073d); scale check vs CS-06 Final Report 2025, p.1 | G17: Selected scenario | H17: 1 | I17: enter 1 or 2
A18: Energy per hour | B18: =B17/1000 -> 0.512 | C18: kWh | G18: 1: Harrison 2025 as measured | H18: 512 | I18: W
A19: Energy per day | B19: =B18*24 -> 12.288 | C19: kWh | G19: 2: CS-06 10x energy target | H19: 51.2 | I19: W
A20: Efficiency: energy per tonne of aerosol | B20: =B19/B14 -> 30334.501 | C20: kWh/tonne | D20: x power price = marginal $/tonne (~$9,100 at $0.30/kWh diesel). CS-06's ARIEL is roughly equal per-particle; CS-06 wants a further ~10x. | G20: B17 reads the selection; tab 2 and every output tab read B17.
A22: Water Handling
A23: Seawater flow rate | B23: 0.41 | C23: mL/s | D23: Harrison 2025 (doi:10.1039/d5ea00073d): ~1.73e12 droplets/s from 0.41 mL/s filtered seawater + 0.3 L/s air per nozzle. Field rigs run lower per nozzle: ERL 2025 (doi:10.1088/1748-9326/adccd7), p.2: "320 effervescent nozzles ... assembled into 5 manifold towers atomising a total of 68 ml s-1 of seawater" (about 0.21 mL/s each). Per-second value; next row converts to daily. | E23: Harrison et al. 2025, Environ. Sci.: Atmos. 5, 1071-1080 (doi:10.1039/d5ea00073d); field config: ERL 2025, p.2.
A24: Seawater sprayed | B24: =B23*86.4 -> 35.424 | C24: L/day | D24: 0.41 mL/s x 86,400 = per-day volume, converted once here so downstream stays in day-units. Only ~3.5% is salt.
A25: Seawater intensity | B25: =B24/(B13/1000000)/1000 -> 87.448679 | C25: m3/tonne | D25: Wet volume handled per dry tonne of CCN. Drives pumping/filtration/UV energy (x 0.6 kWh/m3 on Cost Inputs). Computed from the output of Harrison's 2025 nozzle.
A26: Pumping + filtration + UV energy | B26: 0.6 | C26: kWh per m3 seawater | D26: Electricity to lift, filter and UV-treat one cubic metre of seawater before atomizing. Assumption; until 10/07 this 0.6 was typed inside formulas on tab 2 (B28) and tab 3a (row 37, column AI).
A27: Process Flow
B29: Seawater intake
B30: ↓
B31: Filtration + UV
B32: ↓
B33: Pressurize seawater
B34: ↓
B35: Compress air
B36: ↓
B37: Effervescent nozzle
B38: ↓
B39: Evaporation
B40: ↓
... B52: Cooling Conversion

Sheet 2. Cost Inputs
A1: DRAFT - Cost Input Sheet
A2: General Parameters
B4: Value | C4: Unit | E4: Notes / Source | F4: Sources
A5: Equipment availability | B5: 0.9 | C5: fraction | E5: Mechanical uptime of the system, accounting for repairs and maintenance downtime | F5: Assumption (mechanical uptime target).
A6: Project lifetime | B6: 15 | C6: years | E6: Hardware life | F6: Assumption (hardware life).
A7: Discount rate | B7: 0.1 | E7: Cost of capital | F7: Assumption (cost of capital).
A8: Exchange rate, AUD to USD | B8: 0.7 | C8: USD per AUD | E8: Used by tab 5c to convert the A$ reef valuation. Until 10/07 typed inside 5c B27. | F8: Assumption (0.70 USD/AUD).
A9: Equipment Sizing
B10: Value | C10: Unit | E10: Notes / Source | F10: Sources
A11: Aerosol per nozzle per year | B11: ='1. Technology Description'!B13*365*$B$5/1000000 -> 0.13306987 | C11: tonnes/yr | E11: g/day x 365 x equipment availability, to tonnes
A12: Particle flux per vessel-unit | B12: =B13*'1. Technology Description'!B8*'1. Technology Description'!B9 -> 1e+16 | C12: particles/s | E12: Output now: nozzles x rate x window fraction. Shows 10^16/s at base (Latham et al. 2012, ~10^15-10^16/s per sprayer); it is no longer a requirement.
A13: Nozzle count (per vessel-unit) | B13: =B14*1000/'1. Technology Description'!B17 -> 8141.3336 | C13: nozzles | E13: Spray power (B14) / watts per nozzle (tab 1 B17). Until 10/07 this was 10^16/s / particles per nozzle, so a better nozzle meant the same count at lower power instead of more nozzles on the same plant.
A14: Spray power per vessel-unit | B14: 4168.3628 | C14: kW | E14: The sizing lever since 10/07: the vessel is built around this power plant and carries as many nozzles as it can run (B13). 4,168 kW = 8,142 nozzles at Harrison's 512 W, so the base case is unchanged. At 51 W the same plant runs 81,400 nozzles: no one has checked that many booms and manifolds (127 ARIEL rigs) fit the modelled vessel, and the seawater intake would be 33 L/s. Same approach as the piggyback's 4.5 MW on tab 3b. | F14: Model structure (power-sized vessel-unit, 10/07). Harrison 2025: 814 nozzles at 10^15/s need 417 kW; 10^16/s about 4.2 MW.
A15: Annual production per vessel-unit (equipment basis) | B15: =B13*B11 -> 1083.3662 | C15: tonnes/yr | E15: Nozzle count x aerosol per nozzle-year (equipment basis)
A17: Operating Expenditure (annual)
A18: 1. Raw Materials
B19: Amount | C19: Unit | D19: Cost/Unit | E19: Notes / Source | F19: Sources
A20: Seawater | B20: ='1. Technology Description'!B25*1000 -> 87448.679 | C20: L/tonne | D20: 0 | E20: Drawn from the sea | F20: Structural: seawater drawn at sea, no purchase cost.
A22: 2. Process Energy
B23: Amount | C23: Unit | D23: Cost/Unit
A24: Energy (compression, atomizes wet seawater) | B24: ='1. Technology Description'!B20 -> 30334.501 | C24: kWh/tonne | D24: 0.3 | E24: Power x 24h per nozzle / aerosol per nozzle. | F24: Derived: tab-1 nozzle power (Harrison 2025) x 24 h x energy price assumption.
A25: Vessel propulsion burn (underway) | B25: 16000 | C25: L/day | D25: 0.9 | E25: PSV cruise ~16.4 m3/day at 10 kn, 22.7 at 12 kn (UT 755L); Brazilian PSV fleet average ~9.3 t/day (Vianna et al. 2025). | F25: Vessel spec sheets: UT 755L PSV ~16.4 m3/day at 10 kn (Hornbeck HOS269). PSV fleet average ~9.3 t/day: Vianna, Ribas, Martins Ferreira Filho & Gribkovskaia (2025), J. Mar. Sci. Eng. 13(4):686 (was attributed to "Adland"). Links: https://horizonoffshoreservices.com/wp-content/uploads/2024/07/HOS269.pdf ; https://www.mdpi.com/2077-1312/13/4/686
A26: Vessel hotel burn (at rest / on station) | B26: 2700 | C26: L/day | D26: =D25 -> 0.9 | E26: Hotel plus light station-keeping.
A27: Fuel tank capacity | B27: 1000000 | C27: L
A28: Seawater pumping + filtration + UV | B28: ='1. Technology Description'!B25*'1. Technology Description'!B26 -> 52.469208 | C28: kWh/tonne | D28: 0.3 | E28: Lift, filter, UV-treat seawater before atomizing. Scales with wet volume (~87 m3 per dry tonne). | F28: Assumption: scales with wet volume (~87 m3 per dry tonne).
A29: 3. Labor
B30: Amount | C30: Unit | D30: Cost/Unit
A31: Crew | B31: 6 | C31: crew | D31: 150000 | E31: 6 crew per vessel x vessels (base scenario vessel count lives on tab 3a). | F31: Assumption: 6 crew per vessel.
A33: 4. Fixed Operating Expenditure
B34: Amount | C34: Unit
A35: Maintenance & insurance | B35: 0.07 | C35: of capex/yr | E35: 5% maintenance + 2% insurance | F35: Assumption: 5% maintenance + 2% insurance of capital.
A37: Capital Expenditure
A38: 5. Purchased Equipment
B39: Amount | C39: Unit | D39: Cost/Unit | E39: Notes / Source | F39: Sources | G39: Nozzle unit cost scenario (selector)
A40: Nozzles & manifolds | B40: =B13 -> 8141.3336 | C40: nozzles | D40: =CHOOSE($H$40,$H$41,$H$42,$H$43) -> 100 | E40: No published price for the SCU/ARIEL effervescent nozzle (searched Harrison 2025, CS-01/04/06/07, T14, ARIA proposal, Hernandez-Jaramillo thesis, 10/07). Bracket: CS-07 2025 p.31 'commercially proven nozzles ... ~$10 to ~$1000 each', marine 316 SS 'considerably more expensive'; CS-07 p.35 MeeFog manifolds 'about US$50 per nozzle, including nozzles, adapters, fittings, support frame'; CS-06 p.23 cartridge redesign 'significantly reducing costs'. Scenario 2 ($100) assumes the prototype nozzle unchanged, just made in volume. Compressors are priced separately (row 41). Installation (row 51) is 20% of equipment, so it scales with this price; a flat per-nozzle labour cost would be more honest at $10. | F40: RRAP CS-07 Fogging Development Final Report 2025, p.31 and p.35 (MeeFog manifold US$50/nozzle); RRAP CS-06 Final Report 2025, p.23 (cartridge nozzle). No price for the ARIEL nozzle in any Harrison-group publication. | G40: Selected scenario | H40: 2 | I40: enter 1, 2 or 3
A41: Compression + generation | B41: =B14 -> 4168.3628 | C41: kW | D41: 1500 | E41: Used Ariel 200 hp CNG compressor package listed $180k ≈ $1,200/kW (Bakersfield yard listing). Link: https://inventory.freeoilfieldquote.com/product/ariel-jgq-2-3-200-hp-vfd-electric-drive-3-stage-cng-com | F41: Market reference (website): used Ariel 200 hp CNG compressor package listed $180k, ~$1,200/kW (Bakersfield yard listing). Link: https://inventory.freeoilfieldquote.com/product/ariel-jgq-2-3-200-hp-vfd-electric-drive-3-stage-cng-com | G41: 1: $10, commodity nozzle at volume | H41: 10 | I41: $/nozzle
A42: Seawater intake/filtration/UV | B42: 1 | C42: per vessel | D42: 25000 | E42: $25k marinized: pump + strainer + polish + UV + spares. Ballast-water systems cost $640k+ but treat ~1,000x our throughput (Transport Canada, Transactions on BWTS 2015). | F42: Assumption ($25k marinized); ballast-water treatment systems ($640k+, Transport Canada 'Transactions on BWTS' 2015) as comparator at ~1,000x throughput. Link: https://www.tc.canada.ca/sites/default/files/migrated/transactions_for_bwts_on_the_great_lakes___transport_canada.pdf | G42: 2: $100, cartridge nozzle in a welded manifold, made in volume | H42: 100 | I42: $/nozzle
A43: Vessel structure & integration | B43: 1 | C43: per vessel | D43: =D44*0.25 -> 7500000 | E43: Assumption: nothing published exists for installing a ~1,000-nozzle spray array. Set at 25% of vessel cost. | G43: 3: $1,000, installed research-grade nozzle | H43: 1000 | I43: $/nozzle
A44: Vessel purchase | B44: 1 | C44: vessels | D44: 30000000 | E44: Newbuild 70-80 m PSV (Clarksons basis), sized for the ~3 MW spray plant. Platform = ~6-7 such vessels (sizing block below). | F44: Market reference (website): newbuild 70-80 m PSV, Clarksons basis; sized for the ~3 MW spray plant. Link: https://www.rivieramm.com/news-content-hub/sticker-shock-price-of-psv-newbuildings-up-68-since-2016-79964 | G44: D40 reads the selection; every capex line reads D40. The 3a tornado runs $10 to $1,000 regardless of the selection.
A45: Total purchased equipment | B45: =B40*D40+B41*D41+B42*D42+B43*D43+B44*D44 -> 44591678
...

Sheet 3a. Outputs - Dedicated Vessel
A1: Output Sheet
A3: Annualized Cost Build-up | F3: Key Metrics
A4: Component | B4: Annual cost | C4: $/tonne of aerosol | D4: % of total | F4: Metric | G4: Value | H4: Unit
A5: Capital recovery factor | B5: =('2. Cost Inputs'!B7*(1+'2. Cost Inputs'!B7)^'2. Cost Inputs'!B6)/((1+'2. Cost Inputs'!B7)^'2. Cost Inputs'!B6-1) -> 0.13147378 | F5: Levelized cost of aerosol | G5: =B13/$B$22 -> 54047.979 | H5: $/tonne of aerosol
A6: Annualized capital | B6: ='2. Cost Inputs'!B53*B5 -> 9566691.9 | C6: =B6/$B$22 -> 24173.562 | D6: =B6/$B$13 -> 0.44726117 | F6: Annual aerosol production | G6: =$B$22 -> 395.7502 | H6: tonnes/yr
A7: Energy | B7: ='2. Cost Inputs'!B24*'2. Cost Inputs'!D24*$B$22 -> 3601465.4 | C7: =B7/$B$22 -> 9100.3504 | D7: =B7/$B$13 -> 0.16837541 | F7: Total capex | G7: ='2. Cost Inputs'!B53 -> 72765020 | H7: $
A8: Seawater pumping + filtration | B8: ='2. Cost Inputs'!B28*'2. Cost Inputs'!D28*$B$22 -> 6229.4098 | C8: =B8/$B$22 -> 15.740762 | D8: =B8/$B$13 -> 0.00029123684 | F8: Total annual cost | G8: =B13 -> 21389498 | H8: $/yr
A9: Seawater feedstock | B9: ='2. Cost Inputs'!B20*'2. Cost Inputs'!D20*$B$22 -> 0 | C9: =B9/$B$22 -> 0 | D9: =B9/$B$13 -> 0 | F9: Nozzles per system | G9: ='2. Cost Inputs'!B13 -> 8141.3336 | H9: nozzles
A10: Crew | B10: ='2. Cost Inputs'!B31*'2. Cost Inputs'!D31 -> 900000 | C10: =B10/$B$22 -> 2274.1619 | D10: =B10/$B$13 -> 0.042076724 | F10: Operating days per year | G10: =B21 -> 132 | H10: days/yr
A11: Maintenance & insurance | B11: ='2. Cost Inputs'!B53*'2. Cost Inputs'!B35 -> 5093551.4 | C11: =B11/$B$22 -> 12870.622 | D11: =B11/$B$13 -> 0.23813328 | F11: Spray power | G11: ='2. Cost Inputs'!B14 -> 4168.3628 | H11: kW
A12: Vessel energy | B12: =(B24+B25)*'2. Cost Inputs'!D25 -> 2221560 | C12: =B12/$B$22 -> 5613.5411 | D12: =B12/$B$13 -> 0.10386218 | F12: Capex share of annual cost | G12: =B6/B13 -> 0.44726117 | H12: fraction
A13: Total Annual Cost | B13: =SUM(B6:B12) -> 21389498 | C13: =B13/$B$22 -> 54047.979 | D13: =1 -> 1 | F13: Variable cost share | G13: =(B7+B8)/B13 -> 0.16866664 | H13: fraction
A14: Total incl. diesel CO2 at tab 2 carbon price (added 2026-10) | B14: =B13+G15*'2. Cost Inputs'!$B$63*$B$22 -> 24122572 | C14: =B14/$B$22 -> 60954.037 | F14: Cost per delivered tonne | G14: =G5/'5a. Cooling Model - Local'!B5 -> 180159.93 | H14: $/tonne delivered at cloud base
F15: Diesel CO2 per tonne of aerosol (added 2026-10) | G15: =('2. Cost Inputs'!$B$24*'2. Cost Inputs'!$B$64+($B$24+$B$25)*'2. Cost Inputs'!$B$62/$B$22)/1000*'2. Cost Inputs'!$B$61 -> 36.347678 | H15: t CO2 / tonne of aerosol
A16: Mission & Endurance
A17: Component | E17: Notes | I17: Sources
A18: Spray time - moving (underway) | B18: 0.3652968 | C18: % of avail. time | E18: Spraying while the vessel is underway - the dedicated vessel sprays on the move | I18: Assumption: dedicated vessel sprays underway.
A19: Spray time - on station | B19: 0 | C19: % of avail. time | E19: Spraying while holding station; zero for the dedicated vessel | I19: Assumption: zero on-station for this scenario.
A20: Transit time (no spray) | B20: 0.03652968 | C20: % of avail. time | E20: Repositioning between spray areas plus refuel legs; only propulsion+hotel burn | I20: Assumption: repositioning + refuel legs.
A21: Operating days per year | B21: =(B18+B19+B20)*365*'2. Cost Inputs'!$B$5 -> 132 | C21: days | E21: = (spray + transit) % of available time x 365 x equipment availability
A22: Effective production | B22: =(B18+B19)*'2. Cost Inputs'!$B$15 -> 395.7502 | C22: tonnes/yr | E22: = spray % x equipment-basis annual production (availability already applied)
A23: Endurance per tank | B23: =$B$26*'2. Cost Inputs'!B27/('2. Cost Inputs'!B25+'2. Cost Inputs'!B26) -> 48.128342 | C23: days | E23: 90% of tank at combined underway burn (propulsion + hotel)
A24: Vessel fuel per year (propulsion) | B24: =(B18+B20)*365*'2. Cost Inputs'!$B$5*'2. Cost Inputs'!B25 -> 2112000 | C24: L/yr | E24: = (spray-moving + transit) % x 365 x availability x underway burn
A25: Hotel fuel per year | B25: =B21*'2. Cost Inputs'!B26 -> 356400 | C25: L/yr | E25: = operating days x hotel burn
A26: Usable fraction of fuel tank | B26: 0.9 | C26: fraction | E26: Tanks are not run dry; 90% usable. Read by B23 here and by tab 3d. Until 10/07 typed inside both formulas.
A27: Levelized cost per tonne of aerosol
A28: Cost build-up with every tornado input at worst / base / best. Particle size fixed; only power per unit varies for nozzle improvements.
A30: Component | B30: Pessimistic | C30: Base | D30: Optimistic
A31: Production (t/yr) | B31: =('2. Cost Inputs'!$B$14*1000/B49)*B50*'1. Technology Description'!$B$9*'1. Technology Description'!$B$12*86400*365*B53/1000 -> 134.55507 | C31: =('2. Cost Inputs'!$B$14*1000/C49)*C50*'1. Technology Description'!$B$9*'1. Technology Description'!$B$12*86400*365*C53/1000 -> 395.7502 | D31: =('2. Cost Inputs'!$B$14*1000/D49)*D50*'1. Technology Description'!$B$9*'1. Technology Description'!$B$12*86400*365*D53/1000 -> 5916.4654 | E31: Rebuilt 2026-10 on the power-sized vessel (tab 2 B14 fixed; nozzles = plant / W per nozzle), with hotel fuel and the tab 2 capex stack. The Base column now equals G5.
A32: Energy intensity (kWh/tonne) | B32: =B49*24/1000/(B50*'1. Technology Description'!$B$9*'1. Technology Description'!$B$12*86400/1000) -> 53531.473 | C32: =C49*24/1000/(C50*'1. Technology Description'!$B$9*'1. Technology Description'!$B$12*86400/1000) -> 30334.501 | D32: =D49*24/1000/(D50*'1. Technology Description'!$B$9*'1. Technology Description'!$B$12*86400/1000) -> 2637.7827
A33: Total capex ($) | B33: =(('2. Cost Inputs'!$B$14*1000/B49)*B54+'2. Cost Inputs'!$B$14*B59+'2. Cost Inputs'!$D$42+B55)*(1+'2. Cost Inputs'!$B$49+'2. Cost Inputs'!$B$50+'2. Cost Inputs'!$B$52)+(('2. Cost Inputs'!$B$14*1000/B49)*B54+'2. Cost Inputs'!$B$14*B59+'2. Cost Inputs'!$D$42)*'2. Cost Inputs'!$B$51 -> 1.1669647e+08 | C33: =(('2. Cost Inputs'!$B$14*1000/C49)*C54+'2. Cost Inputs'!$B$14*C59+'2. Cost Inputs'!$D$42+C55)*(1+'2. Cost Inputs'!$B$49+'2. Cost Inputs'!$B$50+'2. Cost Inputs'!$B$52)+(('2. Cost Inputs'!$B$14*1000/C49)*C54+'2. Cost Inputs'!$B$14*C59+'2. Cost Inputs'!$D$42)*'2. Cost Inputs'!$B$51 -> 72765020 | D33: =(('2. Cost Inputs'!$B$14*1000/D49)*D54+'2. Cost Inputs'!$B$14*D59+'2. Cost Inputs'!$D$42+D55)*(1+'2. Cost Inputs'!$B$49+'2. Cost Inputs'!$B$50+'2. Cost Inputs'!$B$52)+(('2. Cost Inputs'!$B$14*1000/D49)*D54+'2. Cost Inputs'!$B$14*D59+'2. Cost Inputs'!$D$42)*'2. Cost Inputs'!$B$51 -> 44263188
A34: Capital recovery factor | B34: =(B57*(1+B57)^'2. Cost Inputs'!B6)/((1+B57)^'2. Cost Inputs'!B6-1) -> 0.17101705 | C34: =(C57*(1+C57)^'2. Cost Inputs'!B6)/((1+C57)^'2. Cost Inputs'!B6-1) -> 0.13147378 | D34: =(D57*(1+D57)^'2. Cost Inputs'!B6)/((1+D57)^'2. Cost Inputs'!B6-1) -> 0.10296276
A35: Annualized capital ($/yr) | B35: =B33*B34 -> 19957086 | C35: =C33*C34 -> 9566691.9 | D35: =D33*D34 -> 4557460.2
A36: Spray energy ($/yr) | B36: =B32*B58*B31 -> 3241318.9 | C36: =C32*C58*C31 -> 3601465.4 | D36: =D32*D58*D31 -> 2809143
A37: Seawater pumping + UV ($/yr) | B37: ='2. Cost Inputs'!$B$28*'2. Cost Inputs'!$D$28*B31 -> 2117.9993 | C37: ='2. Cost Inputs'!$B$28*'2. Cost Inputs'!$D$28*C31 -> 6229.4098 | D37: ='2. Cost Inputs'!$B$28*'2. Cost Inputs'!$D$28*D31 -> 93129.676 | E37: kWh/tonne (tab 2 B28) x price x production for the case. Until 10/07 this row used litres where it needed cubic metres, 1,000x low on a ~$16/tonne line.
A38: Crew ($/yr) | B38: ='2. Cost Inputs'!$B$31*B52 -> 1260000 | C38: ='2. Cost Inputs'!$B$31*C52 -> 900000 | D38: ='2. Cost Inputs'!$B$31*D52 -> 630000
A39: Maintenance & insurance ($/yr) | B39: =B33*B56 -> 13070005 | C39: =C33*C56 -> 5093551.4 | D39: =D33*D56 -> 1549211.6
A40: Vessel energy ($/yr) | B40: =B51*'2. Cost Inputs'!$D$25 -> 3332340 | C40: =C51*'2. Cost Inputs'!$D$25 -> 2221560 | D40: =D51*'2. Cost Inputs'!$D$25 -> 1110780
A41: Levelized cost ($/tonne) | B41: =SUM(B35:B40)/B31 -> 303688.81 | C41: =SUM(C35:C40)/C31 -> 54047.979 | D41: =SUM(D35:D40)/D31 -> 1816.9166
A45: Sensitivity Analysis
...

Sheet 3b. Outputs - Ship Piggyback
A1: Container Ship Piggyback Scenario
A2: Rent deck slots on container ships already running liners. The spray train is sized to its own 4.5 MW of generation (rows 40-43); liner schedules set the spray fraction.
A3: Piggyback Assumptions
B4: Value | C4: Unit | D4: Notes | G4: Sources
A5: Containerized mounting capital per vessel | B5: 100000 | C5: $/vessel | D5: Gear mounting and integration only, no hull purchased | E5: Assumption: gear mounting and integration only, no hull purchased. | G5: Assumption: gear mounting and integration only, no hull purchased.
A6: Technicians per vessel | B6: 3 | C6: people | D6: Ship crew already covered | E6: Assumption: 3 technicians per vessel. | G6: Assumption: 3 technicians per vessel.
A7: Technician annual cost | B7: 180000 | C7: $/person | D7: Loaded annual cost | E7: Assumption (loaded annual cost). | G7: Assumption (loaded annual cost).
A8: Energy price (own generation: tab 2 diesel rate) | B8: ='2. Cost Inputs'!D24 -> 0.3 | C8: $/kWh | D8: The spray train brings its own gensets (tab 2 row 41 capex), so power is priced at the tab-2 diesel rate. Until 10/07 a separate "shipboard" $0.25 was typed here. | E8: Assumption within noted range: grid ~$0.10-0.15, marine diesel generation ~$0.20-0.35/kWh. | G8: Assumption within noted range: grid ~$0.10-0.15, marine diesel generation ~$0.20-0.35/kWh.
A9: Spray-train energy (compression + atomization) | B9: ='2. Cost Inputs'!B24*B8*$B$43 -> 3888000 | C9: $/yr | D9: kWh/tonne x shipboard price x annual production
A10: Deck-slot rental per vessel per year | B10: 2000000 | C10: $/vessel/yr | D10: Assumption | E10: Assumption (deck-slot rental per vessel-year). | G10: Assumption (deck-slot rental per vessel-year).
A11: Seawater skid, containerized (pumps, filtration, UV) | B11: 80000 | C11: $/vessel | D11: Until 10/07 typed inside the row-22 formula.
A12: Mission & Endurance
A13: Spray time - moving (underway) | B13: 0.3652968 | C13: % of avail. time | D13: % of available time spraying; host vessel is underway on its route regardless | G13: Assumption: host vessel underway on its route regardless.
A14: Spray time - on station | B14: 0 | C14: % of avail. time | D14: Zero: host vessel does not hold station to spray | G14: Structural zero: host vessel does not hold station to spray.
A15: Transit time (no spray) | B15: 0 | C15: % of avail. time | D15: Zero: no dedicated transit legs - host vessel is on its route | G15: Structural zero: no dedicated transit legs.
A16: Operating days per year | B16: =(B13+B14+B15)*365*'2. Cost Inputs'!$B$5 -> 120 | C16: days | D16: = (spray + transit) % of available time x 365 x equipment availability
A17: Fuel & endurance | D17: Host vessel carries fuel; deck-slot rental covers logistics; no tank endurance limit
A19: Recomputed Levelized Cost
B20: $/yr | C20: $/tonne of aerosol | D20: Notes
A21: Nozzles & compression capex | B21: =B42*'2. Cost Inputs'!D40+B42*'1. Technology Description'!B17/1000*'2. Cost Inputs'!D41 -> 7628906.2
A22: Seawater skid + mounting | B22: =B5+B11 -> 180000 | C22: Skid + container mounting, no hull (single vessel)
A23: Total purchased equipment | B23: =B21+B22 -> 7808906.2
A24: Total capex (x1.8 contingency) | B24: =B23*(1+'2. Cost Inputs'!B49+'2. Cost Inputs'!B50+'2. Cost Inputs'!B51+'2. Cost Inputs'!B52) -> 14056031
A25: Capital recovery factor | B25: =('2. Cost Inputs'!B7*(1+'2. Cost Inputs'!B7)^'2. Cost Inputs'!B6)/((1+'2. Cost Inputs'!B7)^'2. Cost Inputs'!B6-1) -> 0.13147378
A26: Annualized capital | B26: =B24*B25 -> 1847999.5 | C26: =B26/$B$43 -> 4325.474
A27: Energy | B27: =B9 -> 3888000 | C27: =B27/$B$43 -> 9100.3504 | D27: Spray-train energy at the shipboard price (B9). Until 10/07 this row priced energy again at the tab-2 diesel rate and the total added B9 on top, counting energy twice.
A28: Technician (replaces crew) | B28: =B6*B7 -> 540000 | C28: =B28/$B$43 -> 1263.9375
A29: Deck-slot rental | B29: =B10 -> 2000000 | C29: =B29/$B$43 -> 4681.2502
A30: Maintenance & insurance | B30: =B24*'2. Cost Inputs'!B35 -> 983922.19 | C30: =B30/$B$43 -> 2302.993
A31: Total Annual Cost | B31: =(B26+B27+B28+B29+B30) -> 9259921.7
A32: Levelized Cost per Tonne | C32: =B31/$B$43 -> 21674.005
A34: Container Ship vs Dedicated Vessel
B35: Value | C35: Unit | D35: Notes
A36: Dedicated vessel: $/tonne of aerosol | B36: ='3a. Outputs - Dedicated Vessel'!G5 -> 54047.979 | C36: From main model
A37: Container ship: $/tonne of aerosol | B37: =C32 -> 21674.005
A38: Cost relative to dedicated vessel | B38: =B37/B36 -> 0.40101417
A40: Host-ship sizing (own generation)
A41: Power per host ship, own gensets | B41: 4500 | C41: kW | D41: 4.5 MW of containerized gensets is 3 to 5 forty-foot boxes; with compressors the train takes ~20-30 TEU of slots. Sizes the train on this tab. Until 10/07 the train was tab 2's 10^16/s unit (4.2 MW) while 6c assumed 2 MW from the host.
A42: Nozzles per host ship | B42: =B41*1000/'1. Technology Description'!B17 -> 8789.0625 | C42: nozzles | D42: Power per ship / watts per nozzle (tab 1 B17).
A43: Production per host ship | B43: =($B$13+$B$14)*$B$42*'2. Cost Inputs'!$B$11 -> 427.2363 | C43: tonnes/yr | D43: Spray fraction x nozzles x aerosol per nozzle-year (tab 2 B11). Read by 6c.
...

Sheet 3c. Outputs - Fixed Platform
A1: Fixed Coastal Platform Scenario
A2: Fixed platforms: stay put, run continuously, shore or renewable power, no propulsion fuel. Shore cable priced since 2026-10 (rows 42-46): a ~4.2 MW platform needs array-class 33-66 kV cable (~$0.24-0.65M/km supply). The earlier $0.8-1.5M/km figure was export-class (132-220 kV).
A3: Platform Assumptions
B4: Value | C4: Unit | D4: Notes | G4: Sources
A5: Platform capital per unit | B5: 3000000 | C5: $/platform | D5: Moored buoy / small jack-up / repurposed barge with mooring. Assumption: purpose-built marine structure, far above a $50k container slot. | G5: Assumption: moored buoy / small jack-up / repurposed barge with mooring.
A6: Technicians per platform | B6: 1 | C6: people | D6: Largely automated; periodic maintenance from shore. Closer to the piggyback technician model than a 6-person crew. | G6: Assumption: largely automated, periodic maintenance from shore.
A7: Technician annual cost | B7: 180000 | C7: $/person | D7: Loaded annual cost incl. boat transfers for maintenance trips. | E7: Assumption (includes boat transfers for maintenance trips).
A8: Shore power price | B8: 0.15 | C8: $/kWh | D8: Shore power, cheaper than marine diesel ($0.30/kWh). Set to 0.30 to model diesel gensets. | G8: Assumption: shore-power price; set to 0.30 to model diesel gensets.
A9: Siting + permitting per platform | B9: 250000 | C9: $/platform | D9: New: environmental review, marine permits, consultation near a populated coast. Amortized as capital. | G9: Assumption: environmental review, marine permits, consultation near a populated coast.
A10: Mooring + station-keeping O&M | B10: 60000 | C10: $/platform/yr | D10: New annual cost: mooring inspection, anti-fouling, station-keeping for a fixed marine structure. | E10: Assumption: mooring inspection, anti-fouling, station-keeping O&M.
A12: Mission & Endurance
A13: Spray time - moving (underway) | B13: 0 | C13: % of avail. time | D13: Zero: fixed platform does not move | G13: Structural zero: fixed platform does not move.
A14: Spray time - on station | B14: 0.3652968 | C14: % of avail. time | D14: % of available time spraying; platform is permanently on station | G14: Assumption: platform permanently on station.
A15: Transit time (no spray) | B15: 0 | C15: % of avail. time | D15: Zero: fixed platform has no transit | G15: Structural zero: no transit legs.
A16: Operating days per year | B16: =(B13+B14+B15)*365*'2. Cost Inputs'!$B$5 -> 120 | C16: days | D16: = (spray + transit) % of available time x 365 x equipment availability
A17: Fuel & endurance | D17: Shore-powered; no fuel endurance limit; crew access in suitable weather windows
A19: Recomputed Levelized Cost
B20: $/yr | C20: $/tonne of aerosol | D20: Notes
A21: Nozzles & compression capex | B21: ='2. Cost Inputs'!B13*'2. Cost Inputs'!D40+'2. Cost Inputs'!B14*'2. Cost Inputs'!D41 -> 7066677.5
A22: Seawater skid | B22: ='2. Cost Inputs'!D42 -> 25000 | C22: Intake/filtration/UV skid, one per platform-edge (single platform)
A23: Platform structure + siting | B23: =B5+B9 -> 3250000 | C23: Fixed offshore structure + permitting, single platform
A24: Total purchased equipment | B24: =B21+B22+B23+B46 -> 13640428
A25: Total capex (contingency stack) | B25: =B24*(1+'2. Cost Inputs'!B49+'2. Cost Inputs'!B50+'2. Cost Inputs'!B51+'2. Cost Inputs'!B52) -> 24552770
A26: Capital recovery factor | B26: =('2. Cost Inputs'!B7*(1+'2. Cost Inputs'!B7)^'2. Cost Inputs'!B6)/((1+'2. Cost Inputs'!B7)^'2. Cost Inputs'!B6-1) -> 0.13147378
A27: Annualized capital | B27: =B25*B26 -> 3228045.3 | C27: =B27/(($B$13+$B$14)*'2. Cost Inputs'!$B$15) -> 8156.7751
A28: Energy (shore power) | B28: ='2. Cost Inputs'!B24*B8*(($B$13+$B$14)*'2. Cost Inputs'!$B$15) -> 1800732.7 | C28: =B28/(($B$13+$B$14)*'2. Cost Inputs'!$B$15) -> 4550.1752 | D28: Same kWh/tonne as main model, priced at shore power. No propulsion fuel: platform does not move.
A29: Technician (replaces crew) | B29: =B6*B7 -> 180000 | C29: =B29/(($B$13+$B$14)*'2. Cost Inputs'!$B$15) -> 454.83237 | D29: Automated platform, minimal staffing
A30: Mooring + station-keeping O&M | B30: =B10 -> 60000 | C30: =B30/(($B$13+$B$14)*'2. Cost Inputs'!$B$15) -> 151.61079
A31: Maintenance & insurance | B31: =B25*'2. Cost Inputs'!B35 -> 1718693.9 | C31: =B31/(($B$13+$B$14)*'2. Cost Inputs'!$B$15) -> 4342.8756 | D31: Same 7% of capex as main model
A32: Total Annual Cost | B32: =B27+B28+B29+B30+B31 -> 6987471.9
A33: Levelized Cost per Tonne | C33: =B32/(($B$13+$B$14)*'2. Cost Inputs'!$B$15) -> 17656.269
A35: Fixed Platform vs Other Sitings
B36: Value | C36: Unit | D36: Notes
A37: Dedicated vessel: $/tonne of aerosol | B37: ='3a. Outputs - Dedicated Vessel'!G5 -> 54047.979
A38: Container ship: $/tonne of aerosol | B38: ='3b. Outputs - Ship Piggyback'!C32 -> 21674.005
A39: Fixed platform: $/tonne of aerosol | B39: =C33 -> 17656.269
A40: Cost relative to dedicated vessel | B40: =B39/B37 -> 0.32667769
A42: Shore power cable (added 2026-10)
A43: Cable length to shore | B43: 5 | C43: km | D43: Assumption: near-shore platform. Set 0 with B8 = 0.30 to model diesel gensets on the platform instead (~$19k/t, which bounds this case). | G43: Assumption.
A44: Array-class subsea cable, supply | B44: 455000 | C44: $/km | D44: 33-66 kV array-class cable, $0.24-0.65M/km supply (NREL ORBIT cable library); 0.455 is the library central. | G44: NREL/WISDEM ORBIT library/cables (github.com/WISDEM/ORBIT); Nunemaker et al. 2020, NREL/TP-5000-77081.
...

Sheet 3d. Outputs - Stationary Vessel
A1: Stationary Vessel Scenario
A2: Transit to position, then hold station. Fuel = hotel burn all days + propulsion on transit days.
A3: Mission & Endurance | G3: Sources
A4: Spray time - moving (underway) | B4: 0 | C4: % of avail. time | D4: Zero: this vessel does not spray while underway | G4: Structural zero: does not spray while underway.
A5: Spray time - on station | B5: 0.3652968 | C5: % of avail. time | D5: Spraying while holding station | G5: Assumption: sprays while holding station.
A6: Transit time (no spray) | B6: 0.01217656 | C6: % of avail. time | D6: Steam out and back; one round trip per year | G6: Assumption: steam out and back, one round trip per year.
A7: Operating days per year | B7: =(B4+B5+B6)*365*'2. Cost Inputs'!$B$5 -> 124 | C7: days | D7: = (spray + transit) % of available time x 365 x equipment availability
A8: Effective production | B8: =(B4+B5)*'2. Cost Inputs'!$B$15 -> 395.7502 | C8: tonnes/yr | D8: = spray % x equipment-basis annual production (availability already applied)
A9: Endurance per tank (on station) | B9: ='3a. Outputs - Dedicated Vessel'!$B$26*'2. Cost Inputs'!B27/'2. Cost Inputs'!B26 -> 333.33333 | C9: days | D9: 90% of tank at hotel burn only - about 11 months on station
A10: Missions per year (tank-limited) | B10: =ROUNDUP(B7/B9,0) -> 1 | C10: missions | D10: Returns to port to refuel this many times
A11: Hotel fuel per year | B11: =B7*'2. Cost Inputs'!B26 -> 334800 | C11: L/yr | D11: = operating days x hotel burn
A12: Transit fuel per year | B12: =(B4+B6)*365*'2. Cost Inputs'!$B$5*'2. Cost Inputs'!B25 -> 64000 | C12: L/yr | D12: = (spray-moving + transit) % x 365 x availability x underway burn
A15: Recomputed Levelized Cost
B16: $/yr | C16: $/tonne of aerosol | D16: Notes
A17: Capital recovery factor | B17: =('2. Cost Inputs'!B7*(1+'2. Cost Inputs'!B7)^'2. Cost Inputs'!B6)/((1+'2. Cost Inputs'!B7)^'2. Cost Inputs'!B6-1) -> 0.13147378
A18: Annualized capital | B18: ='2. Cost Inputs'!B53*B17 -> 9566691.9 | C18: =B18/$B$8 -> 24173.562
A19: Energy (spray) | B19: ='2. Cost Inputs'!B24*'2. Cost Inputs'!D24*$B$8 -> 3601465.4 | C19: =B19/$B$8 -> 9100.3504
A20: Seawater pumping + filtration | B20: ='2. Cost Inputs'!B28*'2. Cost Inputs'!D28*$B$8 -> 6229.4098 | C20: =B20/$B$8 -> 15.740762
A21: Seawater feedstock | B21: ='2. Cost Inputs'!B20*'2. Cost Inputs'!D20*$B$8 -> 0 | C21: =B21/$B$8 -> 0
A22: Crew | B22: ='2. Cost Inputs'!B31*'2. Cost Inputs'!D31 -> 900000 | C22: =B22/$B$8 -> 2274.1619
A23: Maintenance & insurance | B23: ='2. Cost Inputs'!B53*'2. Cost Inputs'!B35 -> 5093551.4 | C23: =B23/$B$8 -> 12870.622
A24: Vessel energy (hotel + transit) | B24: =(B11+B12)*'2. Cost Inputs'!D26 -> 358920 | C24: =B24/$B$8 -> 906.93575 | D24: (operating days x hotel burn + moving days x underway burn) x diesel price
A25: Total Annual Cost | B25: =SUM(B18:B24) -> 19526858
A26: Levelized Cost per Tonne | C26: =B25/$B$8 -> 49341.373
A28: Stationary vs Moving Vessel
B29: Value | C29: Unit | D29: Notes
A30: Moving vessel: $/tonne of aerosol (tab 3a) | B30: ='3a. Outputs - Dedicated Vessel'!G5 -> 54047.979 | C30: From main model
A31: Stationary vessel: $/tonne of aerosol | B31: =C26 -> 49341.373
A32: Saving vs moving vessel | B32: =B30-B31 -> 4706.6054 | C32: $/tonne
A33: Cost relative to moving vessel | B33: =B31/B30 -> 0.91291801

Sheet 4. Scenario Comparison
A1: 4. Scenario Comparison
A2: All values pulled live from tabs 3a-3d (green fill); nothing is computed here. Sources for each number sit on its home tab.
A4: Levelized cost per tonne of aerosol
A5: Scenario | B5: $/tonne | C5: $/yr | D5: vs dedicated (3a) | E5: Note
A6: 3a. Dedicated vessel | B6: ='3a. Outputs - Dedicated Vessel'!G5 -> 54047.979 | C6: ='3a. Outputs - Dedicated Vessel'!B13 -> 21389498 | D6: anchor | E6: Main model.
A7: 3b. Ship piggyback | B7: ='3b. Outputs - Ship Piggyback'!C32 -> 21674.005 | C7: ='3b. Outputs - Ship Piggyback'!B31 -> 9259921.7 | D7: ='3b. Outputs - Ship Piggyback'!B38 -> 0.40101417 | E7: Rent deck slots; host vessel runs its route.
A8: 3c. Fixed platform | B8: ='3c. Outputs - Fixed Platform'!C33 -> 17656.269 | C8: ='3c. Outputs - Fixed Platform'!B32 -> 6987471.9 | D8: ='3c. Outputs - Fixed Platform'!B40 -> 0.32667769 | E8: Moored buoy / jack-up; shore power.
A9: 3d. Stationary vessel | B9: ='3d. Outputs - Stationary Vessel'!C26 -> 49341.373 | C9: ='3d. Outputs - Stationary Vessel'!B25 -> 19526858 | D9: ='3d. Outputs - Stationary Vessel'!B33 -> 0.91291801 | E9: Steam out and back once; holds station.

Sheet 5a. Cooling Model - Local
A1: Cost of Cooling: Cost per Unit of Cooling Produced
A2: Converts cost per tonne of aerosol (from the TEA) into cost per unit of cooling, using the particle-size physics below.
A4: Aerosol Delivery | H4: Sources
A5: Survival factor | B5: 0.3 | C5: fraction | D5: Fraction surviving in-plume coagulation/deposition to cloud base. Open research gap (2025 plume review; CS-06 targets it). Range 0.1-0.5. | H5: Hernandez-Jaramillo et al. 2025a, Front. Mar. Sci. 12:1450175, p.1: effectiveness "depends on what fraction of the sea salt aerosols are incorporated into clouds after being emitted"; still an open research gap, so 0.3 is a scenario choice.
A6: Boundary-layer mixing depth | B6: 900 | C6: m | D6: Measured: plumes reached cloud base at 825-900 m across five GBR campaigns (CS-06 Final Report 2025). | H6: CS-06 Final Report 2025, p.2: "plumes consistently reached cloud base heights (800 - 900 metres) under typical trade-wind and low-wind speed doldrum type atmospheric conditions." ERL 2025 abstract: plume detected "just below cloud bases at 700-900 m altitudes".
A7: Cloud susceptibility
A8: Particles per tonne of salt | B8: ='1. Technology Description'!B11 -> 2.6198345e+20 | C8: #/tonne | D8: From tab 1
A9: Background cloud droplet number | B9: 100 | C9: /cm3 | D9: Natural marine background. CS-06 2025 p.34: GBR runs 50-200/cm3, most common ~100. | H9: CS-06 Final Report 2025, pp.25-26: "background CCN concentrations range from approximately 50 to 200 cm-3... The most common value is near 100 cm-3".
A10: Required droplet addition | B10: =(B18-1)*B9 -> 30 | C10: /cm3 | D10: (Droplet-number enhancement - 1) x background: 0.3 x 100 = add 30/cm3 at the 1.3x base. The measured ceiling (CS-06 p.34) is ~200/cm3 total, i.e. at most +100/cm3 (2.0x).
A11: Area per tonne | B11: =B8*B5/(B10*1000000*B6*1000000) -> 2910.9272 | C11: km2/tonne | D11: Particles available / needed per km2. Not applied as a factor: ~9 in 100 windowed arrivals don't activate at 0.5% SS (field-measured, ERL 2025); worse at 0.2% SS.
A12: Critical activation diameter (Köhler threshold) | B12: 50 | C12: nm | D12: Hernandez-Jaramillo 2025 (ERL): ~50 nm activates at 0.5% SS over the GBR; ~73 nm at 0.2% SS (trade-cumulus Hoppel minimum). | H12: ERL 2025, p.9: "a critical diameter of ~ 50 nm at 0.5% supersaturation (SS) and ~73 nm at 0.2% SS" (GBR seawater).
A13: Unused - do not wire (superseded by cloud availability) | B13: 0.43 | C13: fraction | D13: Neutralized 2026-09-09: overlaps cloud availability, same weather gate, would double-count. No formulas reference this input.
A14: Cloud Radiative Effect
B15: Value | C15: Unit | D15: Notes | H15: Sources
A16: Cloud-top shortwave, 24-h mean | B16: 380 | C16: W/m2 | D16: 24-h mean downwelling SW at cloud top, GBR Dec-Apr. 475 was the DJF 24-h mean at the top of the atmosphere (CERES via NASA POWER: 460-491 at three GBR points), not a daytime value. x ~0.8 free-troposphere transmission (Wood 2021) gives ~380. Solar-geometry check, 14-22S, 1 Dec-30 Apr: 442 W/m2 24-h TOA, 376-385 at cloud top. Changed 2026-10 from 475, which was then multiplied by a 0.4 day/night factor in B20, counting the diurnal cycle twice. | H16: Wood 2021, ACP 21:14507 (doi:10.5194/acp-21-14507-2021), Sect. 2.1: day+night-mean irradiance, free-troposphere transmissivity 0.8, no separate diurnal factor. NASA POWER CERES SYN1deg TOA_SW_DWN climatology. Daily-mean insolation computed from solar geometry in review.
A17: Marine cloud albedo | B17: 0.4 | C17: - | D17: Cloud albedo 0.4 (author choice, kept). Stratocumulus decks run ~0.5-0.6 (Wood 2021). GBR summer trade cumulus is lower: 0.1-0.3 domain average (Harrison et al. 2019 T14, pp.64-65), which would cut the Twomey term A(1-A) from 0.24 to 0.09-0.21. | H17: Assumption: literature-typical stratocumulus albedo. Talked with Graham who suggested 0.30 a lower range.
A18: Droplet-number enhancement | B18: 1.3 | C18: x | D18: 1.3x over a 100/cm3 background (+30/cm3). Zhao et al. 2026 GBR modelling: domain-mean droplet increase 1.14-1.73x (central 1.32). Measured ceiling ~200/cm3, i.e. at most 2.0x (CS-06 p.34). Cooling per tonne scales as ln(r)/(r-1), so a higher ratio lowers cooling per tonne.
A19: Local forcing under brightened cloud | B19: =B16*B17*(1-B17)*(1/3)*LN(B18) -> 7.9758736 | C19: W/m2 | D19: Twomey: Fsw x Ac x (1-Ac) x (1/3) x ln(Nd ratio)
A20: Diurnal factor | B20: 1 | D20: 1.0 because B16 is already a 24-h mean. Was 0.4 on top of a 24-h mean, which counted the diurnal cycle twice. If you prefer a daytime B16 (~720-740 W/m2 at cloud top), set this to the daylight fraction, ~0.52 for 14-22S Dec-Apr. | H20: Wood 2021 (doi:10.5194/acp-21-14507-2021): no separate diurnal factor with day+night-mean irradiance. Daylight fraction 0.52 for 14-22S Dec-Apr computed in review.
A21: Cloud availability | B21: 0.2 | D21: CS-01 Final Report 2025, p.11: susceptible low cloud in summer '20% at the north and increases to 55% at the south'. | H21: CS-01 Final Report 2025, p.11: occurrence of susceptible low cloud in summer "is 20% at the north and increases to 55% at the south"
A22: Realization Factor | B22: =B21*B20 -> 0.2 | D22: Diurnal factor (1.0) x cloud availability
A23: Surface energy budget sensitivity
A24: Aerosol lifetime | B24: 3 | C24: days | D24: Boundary-layer residence (uncertain) | H24: Assumption (boundary-layer residence; uncertain).
A25: Local temperature sensitivity | B25: 0.0225 | C25: degC/(W/m2) | D25: Local forcing to local surface cooling. Harrison et al. 2019, RRAP T14 report. | H25: Harrison et al. 2019 (T14), pp.32-33: relationship "approximately linear... with the gradient of 0.225°C per 10 Wm-2 reduction in solar forcing"
A27: From the Aerosol TEA
B28: Value | C28: Unit | D28: Source
A29: Levelized cost of aerosol | B29: ='3a. Outputs - Dedicated Vessel'!G5 -> 54047.979 | C29: $/tonne of aerosol | D29: Headline from the TEA Outputs tab
A31: Cooling Conversion
B32: Value | C32: Unit | D32: Notes / Source
A33: Cooling produced per tonne of aerosol | B33: =(B19*B25*(B11*100)*B24)*B20*B21 -> 31343.203 | C33: degC-ha-days/tonne | D33: local forcing x local temperature sensitivity x area (ha) x lifetime (days) x realization
A34: Cost of cooling produced | B34: =B29/B33 -> 1.7243923 | C34: $/degC-ha-day | D34: Aerosol cost / cooling per tonne

Sheet 5b. Cooling-Value Sensitivity
A1: Cooling-Value Sensitivity: Cost per Unit of Cooling
A2: One-way sensitivity of cost per degC-ha-day to model and cost drivers.
A3: Sensitivity: what Moves the Cost per Unit Cooling
A4: One-way sensitivity of cost per degC-ha-day. Model drivers scale cooling directly (the 3a tornado can't see them); cost drivers pull live from 3a. Survival is the dominant, softest bar. Particle size fixed at 150 nm.
A5: Driver | B5: Downside input | C5: Base | D5: Upside input | E5: at downside ($) | F5: at base ($) | G5: at upside ($) | H5: Swing ($) | I5: Sources | J5: spacer (hidden) | K5: cost-reducing span | L5: cost-raising span | M5: max (label helper) | N5: tail (hidden)
A6: Model: Marine cloud albedo | B6: 0.3 | C6: ='5a. Cooling Model - Local'!$B$17 -> 0.4 | D6: 0.6 | E6: ='5a. Cooling Model - Local'!$B$34*(('5a. Cooling Model - Local'!$B$17*(1-'5a. Cooling Model - Local'!$B$17))/(B6*(1-B6))) -> 1.9707341 | F6: ='5a. Cooling Model - Local'!$B$34 -> 1.7243923 | G6: ='5a. Cooling Model - Local'!$B$34*(('5a. Cooling Model - Local'!$B$17*(1-'5a. Cooling Model - Local'!$B$17))/(D6*(1-D6))) -> 1.7243923 | H6: =MAX(E6,F6,G6)-MIN(E6,F6,G6) -> 0.24634176 | I6: Sensitivity bounds around the tab 5a base cloud albedo; see tab 5a Sources. | J6: =MIN(E6,F6,G6) -> 1.7243923 | K6: =MAX(0,F6-MIN(E6,G6)) -> 0 | L6: =MAX(0,MAX(E6,G6)-F6) -> 0.24634176 | M6: =J6+K6+L6 -> 1.9707341 | N6: =20-MAX(E6:G6) -> 18.029266
A7: Cost: Energy price | B7: ='3a. Outputs - Dedicated Vessel'!B58 -> 0.45 | C7: ='2. Cost Inputs'!D24 -> 0.3 | D7: ='3a. Outputs - Dedicated Vessel'!D58 -> 0.18 | E7: =MAX('3a. Outputs - Dedicated Vessel'!AJ67,'3a. Outputs - Dedicated Vessel'!AJ68)/'5a. Cooling Model - Local'!$B$33 -> 1.869565 | F7: ='5a. Cooling Model - Local'!$B$34 -> 1.7243923 | G7: =MIN('3a. Outputs - Dedicated Vessel'!AJ67,'3a. Outputs - Dedicated Vessel'!AJ68)/'5a. Cooling Model - Local'!$B$33 -> 1.6082542 | H7: =MAX(E7,F7,G7)-MIN(E7,F7,G7) -> 0.26131073 | J7: =MIN(E7,F7,G7) -> 1.6082542 | K7: =MAX(0,F7-MIN(E7,G7)) -> 0.1161381 | L7: =MAX(0,MAX(E7,G7)-F7) -> 0.14517263 | M7: =J7+K7+L7 -> 1.869565 | N7: =20-MAX(E7:G7) -> 18.130435
A8: Cost: Vessel cost | B8: ='3a. Outputs - Dedicated Vessel'!B55 -> 56250000 | C8: ='2. Cost Inputs'!D43 -> 7500000 | D8: ='3a. Outputs - Dedicated Vessel'!D55 -> 22500000 | E8: =MAX('3a. Outputs - Dedicated Vessel'!AJ61,'3a. Outputs - Dedicated Vessel'!AJ62)/'5a. Cooling Model - Local'!$B$33 -> 2.2116686 | F8: ='5a. Cooling Model - Local'!$B$34 -> 1.7243923 | G8: =MIN('3a. Outputs - Dedicated Vessel'!AJ61,'3a. Outputs - Dedicated Vessel'!AJ62)/'5a. Cooling Model - Local'!$B$33 -> 1.3345713 | H8: =MAX(E8,F8,G8)-MIN(E8,F8,G8) -> 0.8770973 | J8: =MIN(E8,F8,G8) -> 1.3345713 | K8: =MAX(0,F8-MIN(E8,G8)) -> 0.38982102 | L8: =MAX(0,MAX(E8,G8)-F8) -> 0.48727628 | M8: =J8+K8+L8 -> 2.2116686 | N8: =20-MAX(E8:G8) -> 17.788331
A9: Cost: Nozzle unit cost | B9: ='3a. Outputs - Dedicated Vessel'!B54 -> 1000 | C9: ='2. Cost Inputs'!D40 -> 100 | D9: ='3a. Outputs - Dedicated Vessel'!D54 -> 10 | E9: =MAX('3a. Outputs - Dedicated Vessel'!AJ59,'3a. Outputs - Dedicated Vessel'!AJ60)/'5a. Cooling Model - Local'!$B$33 -> 1.9386146 | F9: ='5a. Cooling Model - Local'!$B$34 -> 1.7243923 | G9: =MIN('3a. Outputs - Dedicated Vessel'!AJ59,'3a. Outputs - Dedicated Vessel'!AJ60)/'5a. Cooling Model - Local'!$B$33 -> 1.7029701 | H9: =MAX(E9,F9,G9)-MIN(E9,F9,G9) -> 0.23564448 | J9: =MIN(E9,F9,G9) -> 1.7029701 | K9: =MAX(0,F9-MIN(E9,G9)) -> 0.021422225 | L9: =MAX(0,MAX(E9,G9)-F9) -> 0.21422225 | M9: =J9+K9+L9 -> 1.9386146 | N9: =20-MAX(E9:G9) -> 18.061385
A10: Cost: Annual utilization | B10: ='3a. Outputs - Dedicated Vessel'!B53 -> 0.19726027 | C10: =('3a. Outputs - Dedicated Vessel'!$B$18+'3a. Outputs - Dedicated Vessel'!$B$19)*'2. Cost Inputs'!$B$5 -> 0.32876712 | D10: ='3a. Outputs - Dedicated Vessel'!D53 -> 0.42739726 | E10: =MAX('3a. Outputs - Dedicated Vessel'!AJ57,'3a. Outputs - Dedicated Vessel'!AJ58)/'5a. Cooling Model - Local'!$B$33 -> 2.571544 | F10: ='5a. Cooling Model - Local'!$B$34 -> 1.7243923 | G10: =MIN('3a. Outputs - Dedicated Vessel'!AJ57,'3a. Outputs - Dedicated Vessel'!AJ58)/'5a. Cooling Model - Local'!$B$33 -> 1.4311475 | H10: =MAX(E10,F10,G10)-MIN(E10,F10,G10) -> 1.1403964 | J10: =MIN(E10,F10,G10) -> 1.4311475 | K10: =MAX(0,F10-MIN(E10,G10)) -> 0.2932448 | L10: =MAX(0,MAX(E10,G10)-F10) -> 0.84715164 | M10: =J10+K10+L10 -> 2.571544 | N10: =20-MAX(E10:G10) -> 17.428456
A11: Cost: Crew cost | B11: ='3a. Outputs - Dedicated Vessel'!B52 -> 210000 | C11: ='2. Cost Inputs'!D31 -> 150000 | D11: ='3a. Outputs - Dedicated Vessel'!D52 -> 105000 | E11: =MAX('3a. Outputs - Dedicated Vessel'!AJ55,'3a. Outputs - Dedicated Vessel'!AJ56)/'5a. Cooling Model - Local'!$B$33 -> 1.753415 | F11: ='5a. Cooling Model - Local'!$B$34 -> 1.7243923 | G11: =MIN('3a. Outputs - Dedicated Vessel'!AJ55,'3a. Outputs - Dedicated Vessel'!AJ56)/'5a. Cooling Model - Local'!$B$33 -> 1.7026253 | H11: =MAX(E11,F11,G11)-MIN(E11,F11,G11) -> 0.050789746 | J11: =MIN(E11,F11,G11) -> 1.7026253 | K11: =MAX(0,F11-MIN(E11,G11)) -> 0.021767034 | L11: =MAX(0,MAX(E11,G11)-F11) -> 0.029022712 | M11: =J11+K11+L11 -> 1.753415 | N11: =20-MAX(E11:G11) -> 18.246585
A12: Model: Cloud-top shortwave | B12: 340 | C12: ='5a. Cooling Model - Local'!$B$16 -> 380 | D12: 420 | E12: ='5a. Cooling Model - Local'!$B$34*('5a. Cooling Model - Local'!$B$16/B12) -> 1.927262 | F12: ='5a. Cooling Model - Local'!$B$34 -> 1.7243923 | G12: ='5a. Cooling Model - Local'!$B$34*('5a. Cooling Model - Local'!$B$16/D12) -> 1.5601645 | H12: =MAX(E12,F12,G12)-MIN(E12,F12,G12) -> 0.36709753 | I12: Bounds on the 24-h mean cloud-top SW (5a B16 = 380): 340 (the 5c-alt basis) to 420 (DJF TOA 475-491 x 0.85-0.87 transmission). Were 400/550 around the old 475. Changed 2026-10. | J12: =MIN(E12,F12,G12) -> 1.5601645 | K12: =MAX(0,F12-MIN(E12,G12)) -> 0.16422784 | L12: =MAX(0,MAX(E12,G12)-F12) -> 0.20286969 | M12: =J12+K12+L12 -> 1.927262 | N12: =20-MAX(E12:G12) -> 18.072738
A13: Model: Droplet-number enhancement | B13: 1.14 | C13: ='5a. Cooling Model - Local'!$B$18 -> 1.3 | D13: 1.73 | E13: ='5a. Cooling Model - Local'!$B$34*((LN('5a. Cooling Model - Local'!$B$18)/('5a. Cooling Model - Local'!$B$18-1))/(LN(B13)/(B13-1))) -> 1.6113228 | F13: ='5a. Cooling Model - Local'!$B$34 -> 1.7243923 | G13: ='5a. Cooling Model - Local'!$B$34*((LN('5a. Cooling Model - Local'!$B$18)/('5a. Cooling Model - Local'!$B$18-1))/(LN(D13)/(D13-1))) -> 2.0084712 | H13: =MAX(E13,F13,G13)-MIN(E13,F13,G13) -> 0.39714834 | I13: Zhao et al. 2026 GBR range 1.14-1.73x (doi:10.5194/egusphere-2026-1251). Formula includes the area-per-tonne term (5a B11 ~ 1/(r-1)), so cost scales with (r-1)/ln(r). Was 2 and 4 (both above the 1.3 base) with ln(r) only, which showed losses as gains. Changed 2026-10. | J13: =MIN(E13,F13,G13) -> 1.6113228 | K13: =MAX(0,F13-MIN(E13,G13)) -> 0.11306949 | L13: =MAX(0,MAX(E13,G13)-F13) -> 0.28407885 | M13: =J13+K13+L13 -> 2.0084712 | N13: =20-MAX(E13:G13) -> 17.991529
A14: Model: Aerosol lifetime | B14: 2 | C14: ='5a. Cooling Model - Local'!$B$24 -> 3 | D14: 4 | E14: ='5a. Cooling Model - Local'!$B$34*('5a. Cooling Model - Local'!$B$24/B14) -> 2.5865885 | F14: ='5a. Cooling Model - Local'!$B$34 -> 1.7243923 | G14: ='5a. Cooling Model - Local'!$B$34*('5a. Cooling Model - Local'!$B$24/D14) -> 1.2932942 | H14: =MAX(E14,F14,G14)-MIN(E14,F14,G14) -> 1.2932942 | J14: =MIN(E14,F14,G14) -> 1.2932942 | K14: =MAX(0,F14-MIN(E14,G14)) -> 0.43109808 | L14: =MAX(0,MAX(E14,G14)-F14) -> 0.86219617 | M14: =J14+K14+L14 -> 2.5865885 | N14: =20-MAX(E14:G14) -> 17.413412
A15: Model: Temperature sensitivity | B15: 0.015 | C15: ='5a. Cooling Model - Local'!$B$25 -> 0.0225 | D15: 0.032 | E15: ='5a. Cooling Model - Local'!$B$34*('5a. Cooling Model - Local'!$B$25/B15) -> 2.5865885 | F15: ='5a. Cooling Model - Local'!$B$34 -> 1.7243923 | G15: ='5a. Cooling Model - Local'!$B$34*('5a. Cooling Model - Local'!$B$25/D15) -> 1.2124634 | H15: =MAX(E15,F15,G15)-MIN(E15,F15,G15) -> 1.3741251 | J15: =MIN(E15,F15,G15) -> 1.2124634 | K15: =MAX(0,F15-MIN(E15,G15)) -> 0.51192897 | L15: =MAX(0,MAX(E15,G15)-F15) -> 0.86219617 | M15: =J15+K15+L15 -> 2.5865885 | N15: =20-MAX(E15:G15) -> 17.413412
A16: Model: Cooling realization factor | B16: =0.5*C16 -> 0.1 | C16: ='5a. Cooling Model - Local'!$B$22 -> 0.2 | D16: =2*C16 -> 0.4 | E16: ='5a. Cooling Model - Local'!$B$34*('5a. Cooling Model - Local'!$B$22/B16) -> 3.4487847 | F16: ='5a. Cooling Model - Local'!$B$34 -> 1.7243923 | G16: ='5a. Cooling Model - Local'!$B$34*('5a. Cooling Model - Local'!$B$22/D16) -> 0.86219617 | H16: =MAX(E16,F16,G16)-MIN(E16,F16,G16) -> 2.5865885 | J16: =MIN(E16,F16,G16) -> 0.86219617 | K16: =MAX(0,F16-MIN(E16,G16)) -> 0.86219617 | L16: =MAX(0,MAX(E16,G16)-F16) -> 1.7243923 | M16: =J16+K16+L16 -> 3.4487847 | N16: =20-MAX(E16:G16) -> 16.551215
A17: Model: Survival factor | B17: 0.1 | C17: ='5a. Cooling Model - Local'!$B$5 -> 0.3 | D17: 0.5 | E17: ='5a. Cooling Model - Local'!$B$34*('5a. Cooling Model - Local'!$B$5/B17) -> 5.173177 | F17: ='5a. Cooling Model - Local'!$B$34 -> 1.7243923 | G17: ='5a. Cooling Model - Local'!$B$34*('5a. Cooling Model - Local'!$B$5/D17) -> 1.0346354 | H17: =MAX(E17,F17,G17)-MIN(E17,F17,G17) -> 4.1385416 | J17: =MIN(E17,F17,G17) -> 1.0346354 | K17: =MAX(0,F17-MIN(E17,G17)) -> 0.68975693 | L17: =MAX(0,MAX(E17,G17)-F17) -> 3.4487847 | M17: =J17+K17+L17 -> 5.173177 | N17: =20-MAX(E17:G17) -> 14.826823
A18: Model: W/m2 brightening | B18: =C18*0.5 -> 3.9879368 | C18: ='5a. Cooling Model - Local'!B19 -> 7.9758736 | D18: =C18*2 -> 15.951747

Sheet 5c. Benefit - Local - Reef
A1: Local Benefits: Reef-Wide Brightening (Reef Cooling)
A2: Reef-wide deployment on a chartered seasonal fleet: pay only for the bleaching season. Same-day cooling credit only, no persistence or fleet-mobility bonus. Harrison 2019 below as optimistic gut check.
A3: Local on-target delivery factor | B3: 0.5 | C3: fraction | D3: Fraction of sprayed cooling reaching target reef waters (rest drifts off). Same factor on tab 5d. | G3: Assumption (same factor as 5d).
A4: Our Calculation - Deployment and Cost (Chartered Fleet)
A5: Input | B5: Value | C5: Unit | D5: Source / basis | G5: Sources
A6: Reef area cooled | B6: 30000 | C6: km2 | D6: GBR shallow-reef area, ~3 million ha. Reef-wide domain per Harrison et al. 2019. | G6: Harrison et al. 2019 (T14) reef-wide domain; GBR shallow-reef area ~3 million ha.
A7: Marine heatwave duration | B7: 151 | C7: days | D7: ≈ Harrison's Dec 1 - Apr 30 stress window (151 days ≈ 21.6 weeks). Matches the Zhao tab. Replaces the made-up 12 weeks. | G7: Harrison et al. 2019 (T14), p.39: forcing "accumulated over the entire summer from 1 December to 30 April" (151 days = 21.6 weeks).
A8: Peak per-cloud shortwave reduction | B8: ='5a. Cooling Model - Local'!B19/'5a. Cooling Model - Local'!B16 -> 0.020989141 | C8: fraction | D8: Tab-5a nozzle physics. Per-cloud peak exceeds the reef-wide average under either accounting.
A9: Event-average forcing, our accounting | B9: ='5a. Cooling Model - Local'!B19*'5a. Cooling Model - Local'!B22 -> 1.5951747 | C9: W/m2 | D9: Tab-5a peak x realization factor (daylight x seedable-cloud availability). Same-day credit only.
A10: Bleaching-stress relief implied | B10: =B26*(B9/B35) -> 0.041329527 | C10: fraction | D10: Adopted Harrison relief scaled by dose ratio (our event-average forcing / Harrison anchor forcing). Assumes relief ~linear in dose; only modest extrapolation.
A11: Coverage per tonne | B11: ='5a. Cooling Model - Local'!B11 -> 2910.9272 | C11: km2/tonne | D11: Tab 5a area-per-tonne derivation.
A12: Tonnes per heatwave | B12: =(B6/'5a. Cooling Model - Local'!B11)*(B7/'5a. Cooling Model - Local'!B24)/$B$3 -> 1037.4701 | C12: tonnes | D12: Area / coverage per tonne x 3-day cycles over the heatwave / delivery factor. First-principles event tonnage.
A13: Per-vessel output during event | B13: ='2. Cost Inputs'!$B$15*(B7/365)*'5c-alt. Benefit - Reef (Zhao)'!$B$27 -> 425.77774 | C13: tonnes | D13: Equipment-basis annual production (tab 2 B15, includes 90% availability) x event fraction x 95% spray time within the event (same as 5c-alt B27). Changed 2026-10: was 3a B22 x event fraction, but 3a B22 already carries the dedicated vessel's 33% year-round spray share, so the season was counted twice (6.3 vessels instead of ~2.4).
A14: Vessels required for the event | B14: =B12/B13 -> 2.4366472 | C14: vessels | D14: Event tonnage / per-vessel event output.
A15: Charter rate (bareboat: hull + crew) | B15: ='2. Cost Inputs'!B56/7 -> 21428.571 | C15: $/vessel/day | D15: Tab 2 B56 (weekly) / 7. Hull and crew only; mounted gear is row 22.
A16: Season charter cost | B16: =B14*B7*B15 -> 7884294.1 | C16: $ | D16: Vessels x days x rate.
A17: Temporary mounting & removal | B17: =B14*'3b. Outputs - Ship Piggyback'!B5*2 -> 487329.43 | C17: $ | D17: Tab-3b containerized mounting per vessel, install + removal.
A18: Vessel fuel | B18: =B14*B7*('2. Cost Inputs'!B25+'2. Cost Inputs'!B26)*'2. Cost Inputs'!D25 -> 6192324.6 | D18: Vessels x days x fuel usage (propulsion + hotel) x price
A19: Seasonal operating (spray energy + technicians) | B19: =B12*'2. Cost Inputs'!B24*'2. Cost Inputs'!D24+B14*'3b. Outputs - Ship Piggyback'!B7*(B7/365) -> 9622788.5 | C19: $ | D19: Spray energy + one technician per vessel for the season. Charter includes crew and hull.
A20: Cost per heatwave (chartered, incl. row 22) | B20: =SUM(B16:B19)+B22 -> 25878491 | C20: $ | D20: Pay only for the season: bareboat charter + mounting + fuel + operating + the mounted spray train's capital share (row 22).
A21: Cost per hectare | B21: =B20/(B6*100) -> 8.6261637 | C21: $/ha | D21: Linear in area; same $/ha at any scale.
A22: Mounted spray-train capital (event share) | B22: =B14*B7*'2. Cost Inputs'!B58 -> 1691754.6 | C22: $ | D22: Vessels x days x tab 2 B58 (nozzles, compressors, skid, amortized per vessel-day). Included in row 20.
A23: Reef ROI
A24: Bleaching-stress relief, 2015/16 event | B24: 0.5 | C24: fraction | D24: Harrison et al. 2019, modeled. | G24: Harrison et al. 2019 (T14), p.57: "an average reduction in bleaching stress of ~50 percent in 2015/2016".
A25: Bleaching-stress relief, 2016/17 event | B25: 0.65 | C25: fraction | D25: Harrison et al. 2019, modeled. | G25: Harrison et al. 2019 (T14), p.57: "~65 percent in 2016/2017"
A26: Adopted relief (Harrison) | B26: 0.57 | C26: fraction | D26: Average of the two events. Review 2026-10, not changed: 0.57 is relief on the T14 stress metric. On degree heating weeks, which predict mortality, the same 14 T14 reefs give ~0.45, and coral loss is a threshold function of DHW (Hughes et al. 2018, Nature 556:492, doi:10.1038/s41586-018-0041-2), so the linear scaling of relief into dollars in B10 is not supported. | E26: Calculated: average of the two T14 events (0.5, 0.65).
